Workbook

Sheet ScreenTime vs MentalWellness
A1: Column1 | B1: age | C1: gender | D1: occupation | E1: work_mode | F1: screen_time_hours | G1: work_screen_hours | H1: leisure_screen_hours | I1: sleep_hours | J1: sleep_quality_1_5 | K1: stress_level_0_10 | L1: productivity_0_100 | M1: exercise_minutes_per_week | N1: social_hours_per_week | O1: mental_wellness_index_0_100
A2: U0001 | B2: 33 | C2: Female | D2: Employed | E2: Remote | F2: 10.79 | G2: 5.44 | H2: 5.35 | I2: 6.63 | J2: 1 | K2: 9.3 | L2: 44.7 | M2: 127 | N2: 0.7 | O2: 9.3
A3: U0002 | B3: 28 | C3: Female | D3: Employed | E3: In-person | F3: 7.4 | G3: 0.37 | H3: 7.03 | I3: 8.05 | J3: 3 | K3: 5.7 | L3: 78 | M3: 74 | N3: 2.1 | O3: 56.2
A4: U0003 | B4: 35 | C4: Female | D4: Employed | E4: Hybrid | F4: 9.78 | G4: 1.09 | H4: 8.69 | I4: 6.48 | J4: 1 | K4: 9.1 | L4: 51.8 | M4: 67 | N4: 8 | O4: 3.6
A5: U0004 | B5: 42 | C5: Male | D5: Employed | E5: Hybrid | F5: 11.13 | G5: 0.56 | H5: 10.57 | I5: 6.89 | J5: 1 | K5: 10 | L5: 37 | M5: 0 | N5: 5.7 | O5: 0
A6: U0005 | B6: 28 | C6: Male | D6: Student | E6: Remote | F6: 13.22 | G6: 4.09 | H6: 9.13 | I6: 5.79 | J6: 1 | K6: 10 | L6: 38.5 | M6: 143 | N6: 10.1 | O6: 0
A7: U0006 | B7: 28 | C7: Non-binary/Other | D7: Self-employed | E7: Hybrid | F7: 9.83 | G7: 0.53 | H7: 9.3 | I7: 7.19 | J7: 1 | K7: 10 | L7: 44 | M7: 71 | N7: 10.3 | O7: 5
A8: U0007 | B8: 42 | C8: Non-binary/Other | D8: Retired | E8: Remote | F8: 6.02 | G8: 2.82 | H8: 3.2 | I8: 7.44 | J8: 2 | K8: 6.1 | L8: 64.8 | M8: 141 | N8: 4.7 | O8: 43.7
A9: U0008 | B9: 36 | C9: Male | D9: Employed | E9: In-person | F9: 6.21 | G9: 0.75 | H9: 5.46 | I9: 6.78 | J9: 2 | K9: 5.4 | L9: 87 | M9: 51 | N9: 18.7 | O9: 54.3
A10: U0009 | B10: 26 | C10: Male | D10: Student | E10: In-person | F10: 6.28 | G10: 0.67 | H10: 5.61 | I10: 8.48 | J10: 4 | K10: 1.6 | L10: 91.7 | M10: 149 | N10: 10.1 | O10: 86.8
A11: U0010 | B11: 34 | C11: Male | D11: Employed | E11: Hybrid | F11: 9.37 | G11: 0.84 | H11: 8.53 | I11: 7.78 | J11: 2 | K11: 10 | L11: 42.2 | M11: 50 | N11: 12.7 | O11: 10.7
A12: U0011 | B12: 26 | C12: Male | D12: Student | E12: Remote | F12: 9.87 | G12: 3.02 | H12: 6.85 | I12: 6.4 | J12: 1 | K12: 8.8 | L12: 55.9 | M12: 87 | N12: 6.2 | O12: 21.8
A13: U0012 | B13: 26 | C13: Female | D13: Unemployed | E13: Hybrid | F13: 4.96 | G13: 0.25 | H13: 4.71 | I13: 8.01 | J13: 3 | K13: 4.6 | L13: 88.4 | M13: 188 | N13: 12.5 | O13: 74.3
... A401: U0400 | B401: 39 | C401: Female | D401: Employed | E401: Remote | F401: 8.86 | G401: 3.82 | H401: 5.04 | I401: 6.55 | J401: 1 | K401: 10 | L401: 41.4 | M401: 88 | N401: 9.8 | O401: 8.4

Sheet Removed Outlier for productivit
A1: Column1 | B1: age | C1: gender | D1: occupation | E1: work_mode | F1: screen_time_hours | G1: work_screen_hours | H1: leisure_screen_hours | I1: stress_level_0_10 | J1: productivity_0_100 | K1: exercise_minutes_per_week | L1: social_hours_per_week | M1: outlier Productivity
A2: U0001 | B2: 33 | C2: Female | D2: Employed | E2: Remote | F2: 10.79 | G2: 5.44 | H2: 5.35 | I2: 9.3 | J2: 44.7 | K2: 127 | L2: 0.7 | M2: =IF(OR(ScreenTime_vs_MentalWellness__2[[#This Row],[productivity_0_100]] < 'Productivity IQR'!$D$2, ScreenTime_vs_MentalWellness__2[[#This Row],[productivity_0_100]] > 'Productivity IQR'!$D$3), "remove", "keep") -> keep
A3: U0002 | B3: 28 | C3: Female | D3: Employed | E3: In-person | F3: 7.4 | G3: 0.37 | H3: 7.03 | I3: 5.7 | J3: 78 | K3: 74 | L3: 2.1 | M3: =IF(OR(ScreenTime_vs_MentalWellness__2[[#This Row],[productivity_0_100]] < 'Productivity IQR'!$D$2, ScreenTime_vs_MentalWellness__2[[#This Row],[productivity_0_100]] > 'Productivity IQR'!$D$3), "remove", "keep") -> keep
A4: U0003 | B4: 35 | C4: Female | D4: Employed | E4: Hybrid | F4: 9.78 | G4: 1.09 | H4: 8.69 | I4: 9.1 | J4: 51.8 | K4: 67 | L4: 8 | M4: =IF(OR(ScreenTime_vs_MentalWellness__2[[#This Row],[productivity_0_100]] < 'Productivity IQR'!$D$2, ScreenTime_vs_MentalWellness__2[[#This Row],[productivity_0_100]] > 'Productivity IQR'!$D$3), "remove", "keep") -> keep
A5: U0004 | B5: 42 | C5: Male | D5: Employed | E5: Hybrid | F5: 11.13 | G5: 0.56 | H5: 10.57 | I5: 10 | J5: 37 | K5: 0 | L5: 5.7 | M5: =IF(OR(ScreenTime_vs_MentalWellness__2[[#This Row],[productivity_0_100]] < 'Productivity IQR'!$D$2, ScreenTime_vs_MentalWellness__2[[#This Row],[productivity_0_100]] > 'Productivity IQR'!$D$3), "remove", "keep") -> keep
A6: U0005 | B6: 28 | C6: Male | D6: Student | E6: Remote | F6: 13.22 | G6: 4.09 | H6: 9.13 | I6: 10 | J6: 38.5 | K6: 143 | L6: 10.1 | M6: =IF(OR(ScreenTime_vs_MentalWellness__2[[#This Row],[productivity_0_100]] < 'Productivity IQR'!$D$2, ScreenTime_vs_MentalWellness__2[[#This Row],[productivity_0_100]] > 'Productivity IQR'!$D$3), "remove", "keep") -> keep
A7: U0006 | B7: 28 | C7: Non-binary/Other | D7: Self-employed | E7: Hybrid | F7: 9.83 | G7: 0.53 | H7: 9.3 | I7: 10 | J7: 44 | K7: 71 | L7: 10.3 | M7: =IF(OR(ScreenTime_vs_MentalWellness__2[[#This Row],[productivity_0_100]] < 'Productivity IQR'!$D$2, ScreenTime_vs_MentalWellness__2[[#This Row],[productivity_0_100]] > 'Productivity IQR'!$D$3), "remove", "keep") -> keep
A8: U0007 | B8: 42 | C8: Non-binary/Other | D8: Retired | E8: Remote | F8: 6.02 | G8: 2.82 | H8: 3.2 | I8: 6.1 | J8: 64.8 | K8: 141 | L8: 4.7 | M8: =IF(OR(ScreenTime_vs_MentalWellness__2[[#This Row],[productivity_0_100]] < 'Productivity IQR'!$D$2, ScreenTime_vs_MentalWellness__2[[#This Row],[productivity_0_100]] > 'Productivity IQR'!$D$3), "remove", "keep") -> keep
A9: U0008 | B9: 36 | C9: Male | D9: Employed | E9: In-person | F9: 6.21 | G9: 0.75 | H9: 5.46 | I9: 5.4 | J9: 87 | K9: 51 | L9: 18.7 | M9: =IF(OR(ScreenTime_vs_MentalWellness__2[[#This Row],[productivity_0_100]] < 'Productivity IQR'!$D$2, ScreenTime_vs_MentalWellness__2[[#This Row],[productivity_0_100]] > 'Productivity IQR'!$D$3), "remove", "keep") -> keep
A10: U0009 | B10: 26 | C10: Male | D10: Student | E10: In-person | F10: 6.28 | G10: 0.67 | H10: 5.61 | I10: 1.6 | J10: 91.7 | K10: 149 | L10: 10.1 | M10: =IF(OR(ScreenTime_vs_MentalWellness__2[[#This Row],[productivity_0_100]] < 'Productivity IQR'!$D$2, ScreenTime_vs_MentalWellness__2[[#This Row],[productivity_0_100]] > 'Productivity IQR'!$D$3), "remove", "keep") -> keep
A11: U0010 | B11: 34 | C11: Male | D11: Employed | E11: Hybrid | F11: 9.37 | G11: 0.84 | H11: 8.53 | I11: 10 | J11: 42.2 | K11: 50 | L11: 12.7 | M11: =IF(OR(ScreenTime_vs_MentalWellness__2[[#This Row],[productivity_0_100]] < 'Productivity IQR'!$D$2, ScreenTime_vs_MentalWellness__2[[#This Row],[productivity_0_100]] > 'Productivity IQR'!$D$3), "remove", "keep") -> keep
A12: U0011 | B12: 26 | C12: Male | D12: Student | E12: Remote | F12: 9.87 | G12: 3.02 | H12: 6.85 | I12: 8.8 | J12: 55.9 | K12: 87 | L12: 6.2 | M12: =IF(OR(ScreenTime_vs_MentalWellness__2[[#This Row],[productivity_0_100]] < 'Productivity IQR'!$D$2, ScreenTime_vs_MentalWellness__2[[#This Row],[productivity_0_100]] > 'Productivity IQR'!$D$3), "remove", "keep") -> keep
A13: U0012 | B13: 26 | C13: Female | D13: Unemployed | E13: Hybrid | F13: 4.96 | G13: 0.25 | H13: 4.71 | I13: 4.6 | J13: 88.4 | K13: 188 | L13: 12.5 | M13: =IF(OR(ScreenTime_vs_MentalWellness__2[[#This Row],[productivity_0_100]] < 'Productivity IQR'!$D$2, ScreenTime_vs_MentalWellness__2[[#This Row],[productivity_0_100]] > 'Productivity IQR'!$D$3), "remove", "keep") -> keep
... A394: U0400 | B394: 39 | C394: Female | D394: Employed | E394: Remote | F394: 8.86 | G394: 3.82 | H394: 5.04 | I394: 10 | J394: 41.4 | K394: 88 | L394: 9.8 | M394: =IF(OR(ScreenTime_vs_MentalWellness__2[[#This Row],[productivity_0_100]] < 'Productivity IQR'!$D$2, ScreenTime_vs_MentalWellness__2[[#This Row],[productivity_0_100]] > 'Productivity IQR'!$D$3), "remove", "keep") -> keep

Sheet General Info Of Data set
A1: Row Labels | B1: Count of gender
A2: Female | B2: 217 | D2: Female | E2: 217 | F2: =E2/(SUM($E$2:$E$4)) -> 0.55216285
A3: Male | B3: 168 | D3: Male | E3: 168 | F3: =E3/(SUM($E$2:$E$4)) -> 0.42748092
A4: Non-binary/Other | B4: 8 | D4: Non-binary/Other | E4: 8 | F4: =E4/(SUM($E$2:$E$4)) -> 0.020356234
A5: Grand Total | B5: 393
A7: Row Labels | B7: Count of occupation | D7: Employed | E7: 205 | F7: =E7/SUM($E$7:$E$11) -> 0.5216285
A8: Employed | B8: 205 | D8: Student | E8: 106 | F8: =E8/SUM($E$7:$E$11) -> 0.2697201
A9: Student | B9: 106 | D9: Self-employed | E9: 43 | F9: =E9/SUM($E$7:$E$11) -> 0.10941476
A10: Self-employed | B10: 43 | D10: Unemployed | E10: 26 | F10: =E10/SUM($E$7:$E$11) -> 0.066157761
A11: Unemployed | B11: 26 | D11: Retired | E11: 13 | F11: =E11/SUM($E$7:$E$11) -> 0.03307888
A12: Retired | B12: 13
A13: Grand Total | B13: 393
A15: Row Labels | B15: Count of work_mode | D15: Remote | E15: 150 | F15: =E15/SUM($E$15:$E$17) -> 0.38167939
A16: Remote | B16: 150 | D16: Hybrid | E16: 141 | F16: =E16/SUM($E$15:$E$17) -> 0.35877863
A17: Hybrid | B17: 141 | D17: In-person | E17: 102 | F17: =E17/SUM($E$15:$E$17) -> 0.25954198
A18: In-person | B18: 102
A19: Grand Total | B19: 393
A21: Average of age
A22: 29.804071
A38: productivity_0_100
A40: Mean | B40: 53.51883
A41: Standard Error | B41: 0.70264146
A42: Median | B42: 51.5
A43: Mode | B43: 50.4
A44: Standard Deviation | B44: 13.929324
A45: Sample Variance | B45: 194.02607
A46: Kurtosis | B46: -0.14719292
A47: Skewness | B47: 0.50425204
A48: Range | B48: 71.1
A49: Minimum | B49: 20.6
A50: Maximum | B50: 91.7
A51: Sum | B51: 21032.9
A52: Count | B52: 393

Sheet Productivity IQR
A1: Prod
A2: Q1 | B2: =_xlfn.QUARTILE.INC(ScreenTime_vs_MentalWellness[productivity_0_100], 1) -> 43.6 | C2: Lower | D2: =B2-B4*1.5 -> 14.5
A3: Q3 | B3: =_xlfn.QUARTILE.INC(ScreenTime_vs_MentalWellness[productivity_0_100], 3) -> 63 | C3: Upper | D3: =B3+1.5*B4 -> 92.1
A4: IQR | B4: =B3-B2 -> 19.4

Sheet Stress And Productivity
A1: Column1 | B1: age | C1: gender | D1: work_mode | E1: productivity_0_100 | F1: stress_level_0_10 | G1: Stess 0-100
A2: U0001 | B2: 33 | C2: Female | D2: Remote | E2: 44.7 | F2: 9.3 | G2: =Stress_And_Productivity_1[[#This Row],[stress_level_0_10]]*10 -> 93 | J2: Stress | M2: Productivity
A3: U0002 | B3: 28 | C3: Female | D3: In-person | E3: 78 | F3: 5.7 | G3: =Stress_And_Productivity_1[[#This Row],[stress_level_0_10]]*10 -> 57 | J3: Column1 | M3: Column1
A4: U0003 | B4: 35 | C4: Female | D4: Hybrid | E4: 51.8 | F4: 9.1 | G4: =Stress_And_Productivity_1[[#This Row],[stress_level_0_10]]*10 -> 91
A5: U0004 | B5: 42 | C5: Male | D5: Hybrid | E5: 37 | F5: 10 | G5: =Stress_And_Productivity_1[[#This Row],[stress_level_0_10]]*10 -> 100 | J5: Mean | K5: 8.262341 | M5: Mean | N5: 53.51883
A6: U0005 | B6: 28 | C6: Male | D6: Remote | E6: 38.5 | F6: 10 | G6: =Stress_And_Productivity_1[[#This Row],[stress_level_0_10]]*10 -> 100 | J6: Standard Error | K6: 0.097109342 | M6: Standard Error | N6: 0.70264146
A7: U0006 | B7: 28 | C7: Non-binary/Other | D7: Hybrid | E7: 44 | F7: 10 | G7: =Stress_And_Productivity_1[[#This Row],[stress_level_0_10]]*10 -> 100 | J7: Median | K7: 8.8 | M7: Median | N7: 51.5
A8: U0007 | B8: 42 | C8: Non-binary/Other | D8: Remote | E8: 64.8 | F8: 6.1 | G8: =Stress_And_Productivity_1[[#This Row],[stress_level_0_10]]*10 -> 61 | J8: Mode | K8: 10 | M8: Mode | N8: 50.4
A9: U0008 | B9: 36 | C9: Male | D9: In-person | E9: 87 | F9: 5.4 | G9: =Stress_And_Productivity_1[[#This Row],[stress_level_0_10]]*10 -> 54 | J9: Standard Deviation | K9: 1.9251177 | M9: Standard Deviation | N9: 13.929324
A10: U0009 | B10: 26 | C10: Male | D10: In-person | E10: 91.7 | F10: 1.6 | G10: =Stress_And_Productivity_1[[#This Row],[stress_level_0_10]]*10 -> 16 | J10: Sample Variance | K10: 3.7060782 | M10: Sample Variance | N10: 194.02607
A11: U0010 | B11: 34 | C11: Male | D11: Hybrid | E11: 42.2 | F11: 10 | G11: =Stress_And_Productivity_1[[#This Row],[stress_level_0_10]]*10 -> 100 | J11: Kurtosis | K11: 0.37780765 | M11: Kurtosis | N11: -0.14719292
A12: U0011 | B12: 26 | C12: Male | D12: Remote | E12: 55.9 | F12: 8.8 | G12: =Stress_And_Productivity_1[[#This Row],[stress_level_0_10]]*10 -> 88 | J12: Skewness | K12: -1.050368 | M12: Skewness | N12: 0.50425204
A13: U0012 | B13: 26 | C13: Female | D13: Hybrid | E13: 88.4 | F13: 4.6 | G13: =Stress_And_Productivity_1[[#This Row],[stress_level_0_10]]*10 -> 46 | J13: Range | K13: 8.4 | M13: Range | N13: 71.1
A14: U0013 | B14: 31 | C14: Female | D14: Remote | E14: 33 | F14: 10 | G14: =Stress_And_Productivity_1[[#This Row],[stress_level_0_10]]*10 -> 100 | J14: Minimum | K14: 1.6 | M14: Minimum | N14: 20.6
A15: U0014 | B15: 16 | C15: Female | D15: Remote | E15: 70.7 | F15: 6.3 | G15: =Stress_And_Productivity_1[[#This Row],[stress_level_0_10]]*10 -> 63 | J15: Maximum | K15: 10 | M15: Maximum | N15: 91.7
A16: U0015 | B16: 16 | C16: Male | D16: Hybrid | E16: 53.2 | F16: 10 | G16: =Stress_And_Productivity_1[[#This Row],[stress_level_0_10]]*10 -> 100 | J16: Sum | K16: 3247.1 | M16: Sum | N16: 21032.9
A17: U0016 | B17: 25 | C17: Male | D17: Hybrid | E17: 37.6 | F17: 10 | G17: =Stress_And_Productivity_1[[#This Row],[stress_level_0_10]]*10 -> 100 | J17: Count | K17: 393 | M17: Count | N17: 393
A18: U0017 | B18: 21 | C18: Female | D18: In-person | E18: 60.3 | F18: 10 | G18: =Stress_And_Productivity_1[[#This Row],[stress_level_0_10]]*10 -> 100
A19: U0018 | B19: 32 | C19: Male | D19: Hybrid | E19: 49 | F19: 7 | G19: =Stress_And_Productivity_1[[#This Row],[stress_level_0_10]]*10 -> 70
A20: U0019 | B20: 22 | C20: Male | D20: Hybrid | E20: 85.1 | F20: 4.2 | G20: =Stress_And_Productivity_1[[#This Row],[stress_level_0_10]]*10 -> 42 | Q20: Average (0-100) | R20: Stress | S20: Productivity
A21: U0020 | B21: 18 | C21: Female | D21: Remote | E21: 52 | F21: 9.4 | G21: =Stress_And_Productivity_1[[#This Row],[stress_level_0_10]]*10 -> 94 | Q21: Remote | R21: =AVERAGEIF(Stress_And_Productivity_1[work_mode],"Remote",Stress_And_Productivity_1[Stess 0-100]) -> 86.3 | S21: =AVERAGEIF(Stress_And_Productivity_1[work_mode],"Remote",Stress_And_Productivity_1[productivity_0_100]) -> 50.168
A22: U0021 | B22: 41 | C22: Female | D22: Remote | E22: 48.1 | F22: 10 | G22: =Stress_And_Productivity_1[[#This Row],[stress_level_0_10]]*10 -> 100 | Q22: In-person | R22: =AVERAGEIF(Stress_And_Productivity_1[work_mode],"In-person",Stress_And_Productivity_1[Stess 0-100]) -> 77.95098 | S22: =AVERAGEIF(Stress_And_Productivity_1[work_mode],"In-person",Stress_And_Productivity_1[productivity_0_100]) -> 57.056863
A23: U0022 | B23: 28 | C23: Male | D23: Remote | E23: 53.1 | F23: 8.1 | G23: =Stress_And_Productivity_1[[#This Row],[stress_level_0_10]]*10 -> 81 | Q23: Hybrid | R23: =AVERAGEIF(Stress_And_Productivity_1[work_mode],"Hybrid",Stress_And_Productivity_1[Stess 0-100]) -> 82.092199 | S23: =AVERAGEIF(Stress_And_Productivity_1[work_mode],"Hybrid",Stress_And_Productivity_1[productivity_0_100]) -> 54.524113
A24: U0023 | B24: 30 | C24: Male | D24: In-person | E24: 76.4 | F24: 5.1 | G24: =Stress_And_Productivity_1[[#This Row],[stress_level_0_10]]*10 -> 51
A25: U0024 | B25: 18 | C25: Male | D25: Remote | E25: 77.3 | F25: 3.7 | G25: =Stress_And_Productivity_1[[#This Row],[stress_level_0_10]]*10 -> 37
A26: U0025 | B26: 25 | C26: Male | D26: In-person | E26: 50.3 | F26: 9.8 | G26: =Stress_And_Productivity_1[[#This Row],[stress_level_0_10]]*10 -> 98
A27: U0026 | B27: 30 | C27: Male | D27: Hybrid | E27: 51 | F27: 10 | G27: =Stress_And_Productivity_1[[#This Row],[stress_level_0_10]]*10 -> 100
A28: U0027 | B28: 20 | C28: Male | D28: Remote | E28: 53.3 | F28: 10 | G28: =Stress_And_Productivity_1[[#This Row],[stress_level_0_10]]*10 -> 100
A29: U0028 | B29: 33 | C29: Male | D29: In-person | E29: 60 | F29: 7 | G29: =Stress_And_Productivity_1[[#This Row],[stress_level_0_10]]*10 -> 70
A30: U0029 | B30: 25 | C30: Male | D30: Hybrid | E30: 61.1 | F30: 7.6 | G30: =Stress_And_Productivity_1[[#This Row],[stress_level_0_10]]*10 -> 76
A31: U0030 | B31: 27 | C31: Female | D31: In-person | E31: 38 | F31: 10 | G31: =Stress_And_Productivity_1[[#This Row],[stress_level_0_10]]*10 -> 100
A32: U0031 | B32: 25 | C32: Female | D32: In-person | E32: 52.1 | F32: 8.5 | G32: =Stress_And_Productivity_1[[#This Row],[stress_level_0_10]]*10 -> 85
A33: U0032 | B33: 44 | C33: Female | D33: Remote | E33: 42.6 | F33: 10 | G33: =Stress_And_Productivity_1[[#This Row],[stress_level_0_10]]*10 -> 100
A34: U0033 | B34: 29 | C34: Male | D34: Remote | E34: 60.3 | F34: 7 | G34: =Stress_And_Productivity_1[[#This Row],[stress_level_0_10]]*10 -> 70
A35: U0034 | B35: 21 | C35: Male | D35: Hybrid | E35: 57 | F35: 9.9 | G35: =Stress_And_Productivity_1[[#This Row],[stress_level_0_10]]*10 -> 99
... A38: U0037 | B38: 31 | C38: Female | D38: Hybrid | E38: 45.7 | F38: 9.5 | G38: =Stress_And_Productivity_1[[#This Row],[stress_level_0_10]]*10 -> 95
A39: U0038 | B39: 16 | C39: Female | D39: Hybrid | E39: 68.1 | F39: 6.5 | G39: =Stress_And_Productivity_1[[#This Row],[stress_level_0_10]]*10 -> 65 | R39: SUMMARY OUTPUT
A40: U0039 | B40: 19 | C40: Female | D40: In-person | E40: 49.8 | F40: 9 | G40: =Stress_And_Productivity_1[[#This Row],[stress_level_0_10]]*10 -> 90
A41: U0040 | B41: 31 | C41: Male | D41: Remote | E41: 51.6 | F41: 10 | G41: =Stress_And_Productivity_1[[#This Row],[stress_level_0_10]]*10 -> 100 | R41: Regression Statistics
A42: U0041 | B42: 35 | C42: Female | D42: In-person | E42: 67.4 | F42: 7.2 | G42: =Stress_And_Productivity_1[[#This Row],[stress_level_0_10]]*10 -> 72 | R42: Multiple R | S42: 0.86148121
...

Sheet Group by work mode ANOVA
A1: Column1 | B1: Column2 | C1: Column3 | E1: Column1 | F1: Column2 | G1: Column3 | I1: Column1 | J1: Column2 | K1: Column3 | N1: Remote | O1: In-person | P1: Hybrid | R1: Remote | S1: In-person | T1: Hybrid
W2: Stress
N3: stress_level_0_10 | O3: stress_level_0_10 | P3: stress_level_0_10 | R3: productivity_0_100 | S3: productivity_0_100 | T3: productivity_0_100 | W3: Anova: Single Factor
N4: 9.3 | O4: 5.7 | P4: 9.1 | R4: 44.7 | S4: 78 | T4: 51.8
N5: 10 | O5: 5.4 | P5: 10 | R5: 38.5 | S5: 87 | T5: 37 | W5: SUMMARY
N6: 6.1 | O6: 1.6 | P6: 10 | R6: 64.8 | S6: 91.7 | T6: 44 | W6: Groups | X6: Count | Y6: Sum | Z6: Average | AA6: Variance
N7: 8.8 | O7: 10 | P7: 10 | R7: 55.9 | S7: 60.3 | T7: 42.2 | W7: Remote | X7: 150 | Y7: 1294.5 | Z7: 8.63 | AA7: 3.1010403
N8: 10 | O8: 5.1 | P8: 4.6 | R8: 33 | S8: 76.4 | T8: 88.4 | W8: In-person | X8: 102 | Y8: 795.1 | Z8: 7.795098 | AA8: 4.1872035
N9: 6.3 | O9: 9.8 | P9: 10 | R9: 70.7 | S9: 50.3 | T9: 53.2 | W9: Hybrid | X9: 141 | Y9: 1157.5 | Z9: 8.2092199 | AA9: 3.7491287
N10: 9.4 | O10: 7 | P10: 10 | R10: 52 | S10: 60 | T10: 37.6
N11: 10 | O11: 10 | P11: 7 | R11: 48.1 | S11: 38 | T11: 49
N12: 8.1 | O12: 8.5 | P12: 4.2 | R12: 53.1 | S12: 52.1 | T12: 85.1 | W12: ANOVA
N13: 3.7 | O13: 10 | P13: 10 | R13: 77.3 | S13: 39.6 | T13: 51 | W13: Source of Variation | X13: SS | Y13: df | Z13: MS | AA13: F | AB13: P-value | AC13: F crit
N14: 10 | O14: 9 | P14: 7.6 | R14: 53.3 | S14: 49.8 | T14: 61.1 | W14: Between Groups | X14: 42.942083 | Y14: 2 | Z14: 21.471042 | AA14: 5.9394703 | AB14: 0.0028775631 | AC14: 3.0188619
N15: 10 | O15: 7.2 | P15: 9.9 | R15: 42.6 | S15: 67.4 | T15: 57 | W15: Within Groups | X15: 1409.8406 | Y15: 390 | Z15: 3.6149758
N16: 7 | O16: 8.4 | P16: 9.5 | R16: 60.3 | S16: 51.7 | T16: 45.7
N17: 8.4 | O17: 7.4 | P17: 6.5 | R17: 53.6 | S17: 58.8 | T17: 68.1 | W17: Total | X17: 1452.7826 | Y17: 392
N18: 10 | O18: 8.9 | P18: 6.5 | R18: 51.6 | S18: 49.2 | T18: 56.8
N19: 3.8 | O19: 10 | P19: 8.8 | R19: 77.7 | S19: 27.1 | T19: 44.9
N20: 10 | O20: 5.6 | P20: 9.8 | R20: 37.6 | S20: 74 | T20: 44.8
N21: 4.1 | O21: 10 | P21: 9.4 | R21: 79.6 | S21: 46.3 | T21: 51.7
N22: 10 | O22: 10 | P22: 7.2 | R22: 34.8 | S22: 42.2 | T22: 67.8
N23: 9.3 | O23: 7 | P23: 9.7 | R23: 52.8 | S23: 65.1 | T23: 40.3
N24: 10 | O24: 9.2 | P24: 8.4 | R24: 38.5 | S24: 56 | T24: 51.1 | W24: Productivity
N25: 7.2 | O25: 2.2 | P25: 7.4 | R25: 60 | S25: 88 | T25: 50.3 | W25: Anova: Single Factor
N26: 6.9 | O26: 9.4 | P26: 5.1 | R26: 81 | S26: 45.5 | T26: 76.5
N27: 9.4 | O27: 3 | P27: 7.7 | R27: 45.8 | S27: 88.3 | T27: 59 | W27: SUMMARY
N28: 10 | O28: 7.1 | P28: 4.6 | R28: 48.3 | S28: 55.9 | T28: 68.5 | W28: Groups | X28: Count | Y28: Sum | Z28: Average | AA28: Variance
N29: 2.6 | O29: 6.2 | P29: 10 | R29: 86.3 | S29: 68.7 | T29: 41.5 | W29: Remote | X29: 141 | Y29: 7112.5 | Z29: 50.443262 | AA29: 182.54776
N30: 10 | O30: 8.8 | P30: 4.5 | R30: 38 | S30: 49.9 | T30: 67.7 | W30: In-person | X30: 102 | Y30: 5819.8 | Z30: 57.056863 | AA30: 198.74327
N31: 10 | O31: 6.8 | P31: 6.4 | R31: 43 | S31: 61.4 | T31: 58.3 | W31: Hybrid | X31: 141 | Y31: 7687.9 | Z31: 54.524113 | AA31: 187.91699
N32: 5.4 | O32: 7.7 | P32: 8.3 | R32: 74.5 | S32: 53.9 | T32: 57.1
N33: 10 | O33: 9.5 | P33: 10 | R33: 51.1 | S33: 45.4 | T33: 51.5
N34: 6.8 | O34: 7 | P34: 5.1 | R34: 60.5 | S34: 66.8 | T34: 74.8 | W34: ANOVA
N35: 8.2 | O35: 10 | P35: 4.3 | R35: 66.3 | S35: 42.3 | T35: 68.3 | W35: Source of Variation | X35: SS | Y35: df | Z35: MS | AA35: F | AB35: P-value | AC35: F crit
N36: 4.6 | O36: 10 | P36: 10 | R36: 82.3 | S36: 37.3 | T36: 36.4 | W36: Between Groups | X36: 2740.6448 | Y36: 2 | Z36: 1370.3224 | AA36: 7.2575252 | AB36: 0.0008065915 | AC36: 3.0194111
N37: 6.3 | O37: 6.7 | P37: 5 | R37: 64.4 | S37: 73 | T37: 86.8 | W37: Within Groups | X37: 71938.134 | Y37: 381 | Z37: 188.814
N38: 9.1 | O38: 6.6 | P38: 7.1 | R38: 50.4 | S38: 80.4 | T38: 56.7
N39: 9.3 | O39: 4.8 | P39: 9.3 | R39: 46.5 | S39: 67.4 | T39: 55.1 | W39: Total | X39: 74678.779 | Y39: 383
N40: 10 | O40: 7.9 | P40: 8.4 | R40: 43.9 | S40: 56.7 | T40: 56.2
...

Sheet ScreenTime VS Productivity
A1: Column1 | B1: screen_time_hours | C1: work_screen_hours | D1: leisure_screen_hours | E1: productivity_0_100
A2: U0001 | B2: 10.79 | C2: 5.44 | D2: 5.35 | E2: 44.7 | G2: Screen time (hours)
A3: U0002 | B3: 7.4 | C3: 0.37 | D3: 7.03 | E3: 78 | G3: Q1 | H3: =_xlfn.QUARTILE.INC(B:B,1) -> 7.4125 | J3: Upper | K3: =H4+1.5*H5 -> 15.075
A4: U0003 | B4: 9.78 | C4: 1.09 | D4: 8.69 | E4: 51.8 | G4: Q3 | H4: =_xlfn.QUARTILE.INC(B:B,3) -> 10.4775 | J4: Lower | K4: =H3-1.5*H5 -> 2.815
A5: U0004 | B5: 11.13 | C5: 0.56 | D5: 10.57 | E5: 37 | G5: IQR | H5: =H4-H3 -> 3.065
A6: U0005 | B6: 13.22 | C6: 4.09 | D6: 9.13 | E6: 38.5
A7: U0006 | B7: 9.83 | C7: 0.53 | D7: 9.3 | E7: 44 | G7: Outliers | H7: Validity
A8: U0007 | B8: 6.02 | C8: 2.82 | D8: 3.2 | E8: 64.8 | G8: U0119 | H8: Valid | I8: Workmode is in-person so makes sense that screen time is low
A9: U0008 | B9: 6.21 | C9: 0.75 | D9: 5.46 | E9: 87 | G9: U0156 | H9: Invalid | I9: Workmode is remote, but work screen is less than leisure screen time
A10: U0009 | B10: 6.28 | C10: 0.67 | D10: 5.61 | E10: 91.7 | G10: U0180 | H10: Invalid | I10: Workmode is remote, but only have 3 hours of work screen time
A11: U0010 | B11: 9.37 | C11: 0.84 | D11: 8.53 | E11: 42.2 | G11: U0218 | H11: Invalid | I11: Workmode is hybrid, but only 2 hours of work screen time
A12: U0011 | B12: 9.87 | C12: 3.02 | D12: 6.85 | E12: 55.9 | G12: U0258 | H12: Valid | I12: Currently umemployed so makes sense that screen time is low
A13: U0012 | B13: 4.96 | C13: 0.25 | D13: 4.71 | E13: 88.4 | G13: U0276 | H13: Valid | I13: Workmode is remote so makes sense that screen time is high
A14: U0013 | B14: 12.55 | C14: 6.8 | D14: 5.75 | E14: 33 | G14: U0285 | H14: Valid | I14: Workmode is in-person so makes sense that screen time is low
A15: U0014 | B15: 7.86 | C15: 4.33 | D15: 3.53 | E15: 70.7 | G15: U0352 | H15: Valid | I15: Currently retired so makes sense that screen time is low
A16: U0015 | B16: 9.07 | C16: 0.79 | D16: 8.28 | E16: 53.2
A17: U0016 | B17: 13.49 | C17: 2.82 | D17: 10.67 | E17: 37.6
A18: U0017 | B18: 8.86 | C18: 0.82 | D18: 8.04 | E18: 60.3
A19: U0018 | B19: 7.13 | C19: 0.82 | D19: 6.31 | E19: 49 | G19: Productivity
A20: U0019 | B20: 8.18 | C20: 0.7 | D20: 7.48 | E20: 85.1 | G20: Q1 | H20: =_xlfn.QUARTILE.INC(E:E,1) -> 43.625 | J20: Upper | K20: =H21+1.5*H22 -> 90.4375
A21: U0020 | B21: 10.26 | C21: 5.73 | D21: 4.53 | E21: 52 | G21: Q3 | H21: =_xlfn.QUARTILE.INC(E:E,3) -> 62.35 | J21: Lower | K21: =H20-1.5*H22 -> 15.5375
A22: U0021 | B22: 10.14 | C22: 3.29 | D22: 6.85 | E22: 48.1 | G22: IQR | H22: =H21-H20 -> 18.725
A23: U0022 | B23: 7.52 | C23: 2.89 | D23: 4.63 | E23: 53.1
A24: U0023 | B24: 7.67 | C24: 1.65 | D24: 6.02 | E24: 76.4 | G24: Outliers
A25: U0024 | B25: 5.74 | C25: 2.33 | D25: 3.41 | E25: 77.3 | G25: U0095
A26: U0025 | B26: 8.93 | C26: 0.45 | D26: 8.48 | E26: 50.3 | G26: U0119
A27: U0026 | B27: 7.05 | C27: 0.8 | D27: 6.25 | E27: 51 | G27: U0147
A28: U0027 | B28: 11.3 | C28: 5.17 | D28: 6.13 | E28: 53.3 | G28: U0217
A29: U0028 | B29: 6.61 | C29: 0.33 | D29: 6.28 | E29: 60 | G29: U0258
A30: U0029 | B30: 7.43 | C30: 0.73 | D30: 6.7 | E30: 61.1 | G30: U0352
A31: U0030 | B31: 9.57 | C31: 0.48 | D31: 9.09 | E31: 38 | G31: U0384
A32: U0031 | B32: 6.37 | C32: 0.78 | D32: 5.59 | E32: 52.1
A33: U0032 | B33: 14.35 | C33: 7.54 | D33: 6.81 | E33: 42.6 | G33: screen_time_hours | J33: work_screen_hours | M33: leisure_screen_hours | P33: productivity_0_100
A34: U0033 | B34: 6.89 | C34: 1.25 | D34: 5.64 | E34: 60.3
A35: U0034 | B35: 11.38 | C35: 0.57 | D35: 10.81 | E35: 57 | G35: Mean | H35: 9.1092621 | J35: Mean | K35: 2.2131552 | M35: Mean | N35: 6.8961069 | P35: Mean | Q35: 53.51883
A36: U0035 | B36: 13.05 | C36: 0.65 | D36: 12.4 | E36: 39.6 | G36: Standard Error | H36: 0.12124405 | J36: Standard Error | K36: 0.097583665 | M36: Standard Error | N36: 0.1099482 | P36: Standard Error | Q36: 0.70264146
A37: U0036 | B37: 7.47 | C37: 3.01 | D37: 4.46 | E37: 53.6 | G37: Median | H37: 9.13 | J37: Median | K37: 1.48 | M37: Median | N37: 6.71 | P37: Median | Q37: 51.5
A38: U0037 | B38: 9.93 | C38: 1.89 | D38: 8.04 | E38: 45.7 | G38: Mode | H38: 10.13 | J38: Mode | K38: 0.67 | M38: Mode | N38: 6.28 | P38: Mode | Q38: 50.4
A39: U0038 | B39: 8.08 | C39: 1.25 | D39: 6.83 | E39: 68.1 | G39: Standard Deviation | H39: 2.4035697 | J39: Standard Deviation | K39: 1.9345208 | M39: Standard Deviation | N39: 2.1796381 | P39: Standard Deviation | Q39: 13.929324
A40: U0039 | B40: 7.88 | C40: 0.39 | D40: 7.49 | E40: 49.8 | G40: Sample Variance | H40: 5.7771472 | J40: Sample Variance | K40: 3.7423706 | M40: Sample Variance | N40: 4.7508223 | P40: Sample Variance | Q40: 194.02607
...

Sheet ScreenTime and Productivity
A1: work_screen_hours | B1: leisure_screen_hours | C1: productivity_0_100 | D1: screen_time_hours
A2: 5.44 | B2: 5.35 | C2: 44.7 | D2: 10.79 | F2: Statistical Test (Regression)
A3: 0.37 | B3: 7.03 | C3: 78 | D3: 7.4
A4: 1.09 | B4: 8.69 | C4: 51.8 | D4: 9.78 | F4: SUMMARY OUTPUT | G4: Productivity VS Screen time
A5: 0.56 | B5: 10.57 | C5: 37 | D5: 11.13
A6: 4.09 | B6: 9.13 | C6: 38.5 | D6: 13.22 | F6: Regression Statistics
A7: 0.53 | B7: 9.3 | C7: 44 | D7: 9.83 | F7: Multiple R | G7: 0.68076171 | I7: Moderately strong relationship
A8: 2.82 | B8: 3.2 | C8: 64.8 | D8: 6.02 | F8: R Square | G8: 0.46343651 | I8: 46.3 percent of the change in productivity is because of screen time
A9: 0.75 | B9: 5.46 | C9: 87 | D9: 6.21 | F9: Adjusted R Square | G9: 0.46205362
A10: 0.67 | B10: 5.61 | C10: 91.7 | D10: 6.28 | F10: Standard Error | G10: 10.140258
A11: 0.84 | B11: 8.53 | C11: 42.2 | D11: 9.37 | F11: Observations | G11: 390
A12: 3.02 | B12: 6.85 | C12: 55.9 | D12: 9.87
A13: 0.25 | B13: 4.71 | C13: 88.4 | D13: 4.96 | F13: ANOVA
A14: 6.8 | B14: 5.75 | C14: 33 | D14: 12.55 | G14: df | H14: SS | I14: MS | J14: F | K14: Significance F
A15: 4.33 | B15: 3.53 | C15: 70.7 | D15: 7.86 | F15: Regression | G15: 1 | H15: 34458.701 | I15: 34458.701 | J15: 335.12039 | K15: 2.0867295e-54
A16: 0.79 | B16: 8.28 | C16: 53.2 | D16: 9.07 | F16: Residual | G16: 388 | H16: 39896.039 | I16: 102.82484
A17: 2.82 | B17: 10.67 | C17: 37.6 | D17: 13.49 | F17: Total | G17: 389 | H17: 74354.74
A18: 0.82 | B18: 8.04 | C18: 60.3 | D18: 8.86
A19: 0.82 | B19: 6.31 | C19: 49 | D19: 7.13 | G19: Coefficients | H19: Standard Error | I19: t Stat | J19: P-value | K19: Lower 95% | L19: Upper 95% | M19: Lower 95.0% | N19: Upper 95.0%
A20: 0.7 | B20: 7.48 | C20: 85.1 | D20: 8.18 | F20: Intercept | G20: 90.209484 | H20: 2.0594611 | I20: 43.80247 | J20: 2.895237e-152 | K20: 86.160384 | L20: 94.258584 | M20: 86.160384 | N20: 94.258584
A21: 5.73 | B21: 4.53 | C21: 52 | D21: 10.26 | F21: X Variable 1 | G21: -4.0315577 | H21: 0.22022796 | I21: -18.306294 | J21: 2.0867295e-54 | K21: -4.4645472 | L21: -3.5985682 | M21: -4.4645472 | N21: -3.5985682
A22: 3.29 | B22: 6.85 | C22: 48.1 | D22: 10.14
A23: 2.89 | B23: 4.63 | C23: 53.1 | D23: 7.52 | G23: Negative X variable means an inverse relationship
A24: 1.65 | B24: 6.02 | C24: 76.4 | D24: 7.67
A25: 2.33 | B25: 3.41 | C25: 77.3 | D25: 5.74 | G25: Low P value number means that the relationship is not random
A26: 0.45 | B26: 8.48 | C26: 50.3 | D26: 8.93
A27: 0.8 | B27: 6.25 | C27: 51 | D27: 7.05 | G27: Screen time definitely has a negative effect on productivity
A28: 5.17 | B28: 6.13 | C28: 53.3 | D28: 11.3
A29: 0.33 | B29: 6.28 | C29: 60 | D29: 6.61 | F29: SUMMARY OUTPUT | G29: Productivity VS Work Screen time
A30: 0.73 | B30: 6.7 | C30: 61.1 | D30: 7.43
A31: 0.48 | B31: 9.09 | C31: 38 | D31: 9.57 | F31: Regression Statistics
A32: 0.78 | B32: 5.59 | C32: 52.1 | D32: 6.37 | F32: Multiple R | G32: 0.31313261 | I32: Weak relationship compared to pure screen time
A33: 7.54 | B33: 6.81 | C33: 42.6 | D33: 14.35 | F33: R Square | G33: 0.098052034 | I33: Work screen time only affects 9.8 percent of productivity
A34: 1.25 | B34: 5.64 | C34: 60.3 | D34: 6.89 | F34: Adjusted R Square | G34: 0.095727426
A35: 0.57 | B35: 10.81 | C35: 57 | D35: 11.38 | F35: Standard Error | G35: 13.147077
A36: 0.65 | B36: 12.4 | C36: 39.6 | D36: 13.05 | F36: Observations | G36: 390
A37: 3.01 | B37: 4.46 | C37: 53.6 | D37: 7.47
A38: 1.89 | B38: 8.04 | C38: 45.7 | D38: 9.93 | F38: ANOVA
A39: 1.25 | B39: 6.83 | C39: 68.1 | D39: 8.08 | G39: df | H39: SS | I39: MS | J39: F | K39: Significance F
A40: 0.39 | B40: 7.49 | C40: 49.8 | D40: 7.88 | F40: Regression | G40: 1 | H40: 7290.6334 | I40: 7290.6334 | J40: 42.180027 | K40: 2.552826e-10
...

Sheet Productivity vs ExerciseMinutes
A1: Column1 | B1: age | C1: gender | D1: productivity_0_100 | E1: exercise_minutes_per_week
A2: U0001 | B2: 33 | C2: Female | D2: 44.7 | E2: 127 | H2: Productivity vs Exercise Minutes
A3: U0002 | B3: 28 | C3: Female | D3: 78 | E3: 74 | H3: SUMMARY OUTPUT
A4: U0003 | B4: 35 | C4: Female | D4: 51.8 | E4: 67
A5: U0004 | B5: 42 | C5: Male | D5: 37 | E5: 0 | H5: Regression Statistics
A6: U0005 | B6: 28 | C6: Male | D6: 38.5 | E6: 143 | H6: Multiple R | I6: 0.13187937
A7: U0006 | B7: 28 | C7: Non-binary/Other | D7: 44 | E7: 71 | H7: R Square | I7: 0.017392167
A8: U0007 | B8: 42 | C8: Non-binary/Other | D8: 64.8 | E8: 141 | H8: Adjusted R Square | I8: 0.014923303
A9: U0008 | B9: 36 | C9: Male | D9: 87 | E9: 51 | H9: Standard Error | I9: 14.907558
A10: U0009 | B10: 26 | C10: Male | D10: 91.7 | E10: 149 | H10: Observations | I10: 400
A11: U0010 | B11: 34 | C11: Male | D11: 42.2 | E11: 50
A12: U0011 | B12: 26 | C12: Male | D12: 55.9 | E12: 87 | H12: ANOVA
A13: U0012 | B13: 26 | C13: Female | D13: 88.4 | E13: 188 | I13: df | J13: SS | K13: MS | L13: F | M13: Significance F
A14: U0013 | B14: 31 | C14: Female | D14: 33 | E14: 139 | H14: Regression | I14: 1 | J14: 1565.5595 | K14: 1565.5595 | L14: 7.0446034 | M14: 0.0082691775
A15: U0014 | B15: 16 | C15: Female | D15: 70.7 | E15: 102 | H15: Residual | I15: 398 | J15: 88449.644 | K15: 222.23529
A16: U0015 | B16: 16 | C16: Male | D16: 53.2 | E16: 0 | H16: Total | I16: 399 | J16: 90015.203
A17: U0016 | B17: 25 | C17: Male | D17: 37.6 | E17: 284
A18: U0017 | B18: 21 | C18: Female | D18: 60.3 | E18: 223 | I18: Coefficients | J18: Standard Error | K18: t Stat | L18: P-value | M18: Lower 95% | N18: Upper 95% | O18: Lower 95.0% | P18: Upper 95.0%
A19: U0018 | B19: 32 | C19: Male | D19: 49 | E19: 167 | H19: Intercept | I19: 51.199448 | J19: 1.3877919 | K19: 36.892742 | L19: 1.6683309e-130 | M19: 48.47113 | N19: 53.927767 | O19: 48.47113 | P19: 53.927767
A20: U0019 | B20: 22 | C20: Male | D20: 85.1 | E20: 52 | H20: exercise_minutes_per_week | I20: 0.028294797 | J20: 0.010660518 | K20: 2.6541672 | L20: 0.0082691775 | M20: 0.0073368336 | N20: 0.049252761 | O20: 0.0073368336 | P20: 0.049252761
A21: U0020 | B21: 18 | C21: Female | D21: 52 | E21: 82
A22: U0021 | B22: 41 | C22: Female | D22: 48.1 | E22: 65
A23: U0022 | B23: 28 | C23: Male | D23: 53.1 | E23: 200
A24: U0023 | B24: 30 | C24: Male | D24: 76.4 | E24: 130 | H24: Analysis
A25: U0024 | B25: 18 | C25: Male | D25: 77.3 | E25: 63 | H25: There is a statiscally significant relationship between Productivity and Exercise Minutes per week because the p-value is low (0.08)
A26: U0025 | B26: 25 | C26: Male | D26: 50.3 | E26: 69
A27: U0026 | B27: 30 | C27: Male | D27: 51 | E27: 194 | H27: However, it shows weak relationship and is not practically useful with a low Multiple R and R Square value of 0.1319 and 0.0174 respectively.
A28: U0027 | B28: 20 | C28: Male | D28: 53.3 | E28: 197
A29: U0028 | B29: 33 | C29: Male | D29: 60 | E29: 227 | H29: The 0.028 Coefficients of Exercise Minutes per week confirms the insignificant validity to the relationship.
A30: U0029 | B30: 25 | C30: Male | D30: 61.1 | E30: 164
A31: U0030 | B31: 27 | C31: Female | D31: 38 | E31: 81
A32: U0031 | B32: 25 | C32: Female | D32: 52.1 | E32: 0
A33: U0032 | B33: 44 | C33: Female | D33: 42.6 | E33: 100
A34: U0033 | B34: 29 | C34: Male | D34: 60.3 | E34: 116
A35: U0034 | B35: 21 | C35: Male | D35: 57 | E35: 95
A36: U0035 | B36: 36 | C36: Male | D36: 39.6 | E36: 86
A37: U0036 | B37: 20 | C37: Female | D37: 53.6 | E37: 15
A38: U0037 | B38: 31 | C38: Female | D38: 45.7 | E38: 138
A39: U0038 | B39: 16 | C39: Female | D39: 68.1 | E39: 147
A40: U0039 | B40: 19 | C40: Female | D40: 49.8 | E40: 153
...

Sheet Productivity vs SocialHours
A1: Column1 | B1: age | C1: gender | D1: productivity_0_100 | E1: social_hours_per_week
A2: U0001 | B2: 33 | C2: Female | D2: 44.7 | E2: 0.7 | H2: Productivity vs Social Hours
A3: U0002 | B3: 28 | C3: Female | D3: 78 | E3: 2.1 | H3: SUMMARY OUTPUT
A4: U0003 | B4: 35 | C4: Female | D4: 51.8 | E4: 8
A5: U0004 | B5: 42 | C5: Male | D5: 37 | E5: 5.7 | H5: Regression Statistics
A6: U0005 | B6: 28 | C6: Male | D6: 38.5 | E6: 10.1 | H6: Multiple R | I6: 0.11723164
A7: U0006 | B7: 28 | C7: Non-binary/Other | D7: 44 | E7: 10.3 | H7: R Square | I7: 0.013743256
A8: U0007 | B8: 42 | C8: Non-binary/Other | D8: 64.8 | E8: 4.7 | H8: Adjusted R Square | I8: 0.011265224
A9: U0008 | B9: 36 | C9: Male | D9: 87 | E9: 18.7 | H9: Standard Error | I9: 14.935212
A10: U0009 | B10: 26 | C10: Male | D10: 91.7 | E10: 10.1 | H10: Observations | I10: 400
A11: U0010 | B11: 34 | C11: Male | D11: 42.2 | E11: 12.7
A12: U0011 | B12: 26 | C12: Male | D12: 55.9 | E12: 6.2 | H12: ANOVA
A13: U0012 | B13: 26 | C13: Female | D13: 88.4 | E13: 12.5 | I13: df | J13: SS | K13: MS | L13: F | M13: Significance F
A14: U0013 | B14: 31 | C14: Female | D14: 33 | E14: 11.3 | H14: Regression | I14: 1 | J14: 1237.102 | K14: 1237.102 | L14: 5.5460367 | M14: 0.019007302
A15: U0014 | B15: 16 | C15: Female | D15: 70.7 | E15: 8.6 | H15: Residual | I15: 398 | J15: 88778.101 | K15: 223.06056
A16: U0015 | B16: 16 | C16: Male | D16: 53.2 | E16: 0 | H16: Total | I16: 399 | J16: 90015.203
A17: U0016 | B17: 25 | C17: Male | D17: 37.6 | E17: 2.8
A18: U0017 | B18: 21 | C18: Female | D18: 60.3 | E18: 13.1 | I18: Coefficients | J18: Standard Error | K18: t Stat | L18: P-value | M18: Lower 95% | N18: Upper 95% | O18: Lower 95.0% | P18: Upper 95.0%
A19: U0018 | B19: 32 | C19: Male | D19: 49 | E19: 11.6 | H19: Intercept | I19: 51.471394 | J19: 1.4166661 | K19: 36.332763 | L19: 1.8291095e-128 | M19: 48.68631 | N19: 54.256478 | O19: 48.68631 | P19: 54.256478
A20: U0019 | B20: 22 | C20: Male | D20: 85.1 | E20: 11.2 | H20: social_hours_per_week | I20: 0.35864714 | J20: 0.15229162 | K20: 2.3550025 | L20: 0.019007302 | M20: 0.0592506 | N20: 0.65804368 | O20: 0.0592506 | P20: 0.65804368
A21: U0020 | B21: 18 | C21: Female | D21: 52 | E21: 1.5
A22: U0021 | B22: 41 | C22: Female | D22: 48.1 | E22: 2.8
A23: U0022 | B23: 28 | C23: Male | D23: 53.1 | E23: 13.2 | H23: Analysis
A24: U0023 | B24: 30 | C24: Male | D24: 76.4 | E24: 8.9 | H24: There is a statiscally significant relationship between Social Hours per week and Productivity, Because the p-value, which is 0.019,
A25: U0024 | B25: 18 | C25: Male | D25: 77.3 | E25: 17.6 | H25: is less than 0.05 which is a standard cut off of 95 CI.
A26: U0025 | B26: 25 | C26: Male | D26: 50.3 | E26: 8.5
A27: U0026 | B27: 30 | C27: Male | D27: 51 | E27: 8.6 | H27: However, the relationship is extremely weak and not practically useful, its weakness can be explained by the low value of Multiple R (0.117) and R Square (0.014).
A28: U0027 | B28: 20 | C28: Male | D28: 53.3 | E28: 7.4
A29: U0028 | B29: 33 | C29: Male | D29: 60 | E29: 3.5 | H29: Our model gives the Coefficients of Social Hours of 0.359. This means that for every additional 1 social hours per week, Productivity is predicted to increase by 0.359,
A30: U0029 | B30: 25 | C30: Male | D30: 61.1 | E30: 0 | H30: which is a very small effect and confirms the weakness of this relationship.
A31: U0030 | B31: 27 | C31: Female | D31: 38 | E31: 9.1
A32: U0031 | B32: 25 | C32: Female | D32: 52.1 | E32: 8.9
A33: U0032 | B33: 44 | C33: Female | D33: 42.6 | E33: 5.1
A34: U0033 | B34: 29 | C34: Male | D34: 60.3 | E34: 0.2
A35: U0034 | B35: 21 | C35: Male | D35: 57 | E35: 11.4
A36: U0035 | B36: 36 | C36: Male | D36: 39.6 | E36: 4.2
A37: U0036 | B37: 20 | C37: Female | D37: 53.6 | E37: 14.3
A38: U0037 | B38: 31 | C38: Female | D38: 45.7 | E38: 15.2
A39: U0038 | B39: 16 | C39: Female | D39: 68.1 | E39: 0
A40: U0039 | B40: 19 | C40: Female | D40: 49.8 | E40: 7.6
...
